{"uid":"d7072c92a2bee4a2","name":"test_restore_file","fullName":"tests.restore_file.test_restore_file#test_restore_file","historyId":"746de96fdc5b17f9d13997d5b62244c5","time":{"start":1683312823490,"stop":1683312823490,"duration":0},"status":"broken","statusMessage":"FileNotFoundError: [Errno 2] No such file or directory: '/home/runner/work/py-pytest/data/input.txt'","statusTrace":"@pytest.fixture()\n    def get_file_id():\n        file_path = os.path.join(os.getcwd(), Links.FILE_PATH)\n        headers = {\"Authorization\": f\"Bearer {Links.ACCESS_TOKEN}\"}\n        params = {\"name\": Links.FILE_NAME, \"parents\": [Links.PARENTS]}\n        files = {\"data\": (\"metadata\", json.dumps(params),\n                          \"application/json; charset=UTF-8\"),\n>                \"file\": open(file_path, \"rb\")}\nE       FileNotFoundError: [Errno 2] No such file or directory: '/home/runner/work/py-pytest/data/input.txt'\n\nconftest.py:39: FileNotFoundError","flaky":false,"newFailed":false,"newBroken":false,"newPassed":false,"retriesCount":0,"retriesStatusChange":false,"beforeStages":[{"name":"_verify_url","time":{"start":1683312814740,"stop":1683312814740,"duration":0},"status":"passed","steps":[],"attachments":[],"parameters":[],"stepsCount":0,"attachmentsCount":0,"shouldDisplayMessage":false,"hasContent":false},{"name":"pytestconfig","time":{"start":1683312814740,"stop":1683312814740,"duration":0},"status":"passed","steps":[],"attachments":[],"parameters":[],"stepsCount":0,"attachmentsCount":0,"shouldDisplayMessage":false,"hasContent":false},{"name":"base_url","time":{"start":1683312814740,"stop":1683312814740,"duration":0},"status":"passed","steps":[],"attachments":[],"parameters":[],"stepsCount":0,"attachmentsCount":0,"shouldDisplayMessage":false,"hasContent":false},{"name":"delete_output_dir","time":{"start":1683312814740,"stop":1683312814741,"duration":1},"status":"passed","steps":[],"attachments":[],"parameters":[],"stepsCount":0,"attachmentsCount":0,"shouldDisplayMessage":false,"hasContent":false},{"name":"update_refresh_token","time":{"start":1683312823490,"stop":1683312823633,"duration":143},"status":"passed","steps":[],"attachments":[],"parameters":[],"stepsCount":0,"attachmentsCount":0,"shouldDisplayMessage":false,"hasContent":false},{"name":"get_file_id","time":{"start":1683312823633,"stop":1683312823633,"duration":0},"status":"broken","statusMessage":"FileNotFoundError: [Errno 2] No such file or directory: '/home/runner/work/py-pytest/data/input.txt'\n","statusTrace":"  File \"/opt/hostedtoolcache/Python/3.11.3/x64/lib/python3.11/site-packages/pluggy/_callers.py\", line 39, in _multicall\n    res = hook_impl.function(*args)\n          ^^^^^^^^^^^^^^^^^^^^^^^^^\n  File \"/opt/hostedtoolcache/Python/3.11.3/x64/lib/python3.11/site-packages/_pytest/fixtures.py\", line 1130, in pytest_fixture_setup\n    result = call_fixture_func(fixturefunc, request, kwargs)\n             ^^^^^^^^^^^^^^^^^^^^^^^^^^^^^^^^^^^^^^^^^^^^^^^\n  File \"/opt/hostedtoolcache/Python/3.11.3/x64/lib/python3.11/site-packages/_pytest/fixtures.py\", line 909, in call_fixture_func\n    fixture_result = fixturefunc(**kwargs)\n                     ^^^^^^^^^^^^^^^^^^^^^\n  File \"/home/runner/work/py-pytest/py-pytest/conftest.py\", line 39, in get_file_id\n    \"file\": open(file_path, \"rb\")}\n            ^^^^^^^^^^^^^^^^^^^^^\n","steps":[],"attachments":[],"parameters":[],"stepsCount":0,"attachmentsCount":0,"shouldDisplayMessage":true,"hasContent":true}],"testStage":{"status":"broken","statusMessage":"FileNotFoundError: [Errno 2] No such file or directory: '/home/runner/work/py-pytest/data/input.txt'","statusTrace":"@pytest.fixture()\n    def get_file_id():\n        file_path = os.path.join(os.getcwd(), Links.FILE_PATH)\n        headers = {\"Authorization\": f\"Bearer {Links.ACCESS_TOKEN}\"}\n        params = {\"name\": Links.FILE_NAME, \"parents\": [Links.PARENTS]}\n        files = {\"data\": (\"metadata\", json.dumps(params),\n                          \"application/json; charset=UTF-8\"),\n>                \"file\": open(file_path, \"rb\")}\nE       FileNotFoundError: [Errno 2] No such file or directory: '/home/runner/work/py-pytest/data/input.txt'\n\nconftest.py:39: FileNotFoundError","steps":[],"attachments":[{"uid":"6b885009dbfdd8a","name":"log","source":"6b885009dbfdd8a.txt","type":"text/plain","size":151},{"uid":"78d916c3f72f0def","name":"stderr","source":"78d916c3f72f0def.txt","type":"text/plain","size":120}],"parameters":[],"stepsCount":0,"attachmentsCount":2,"shouldDisplayMessage":true,"hasContent":true},"afterStages":[],"labels":[{"name":"feature","value":"Проверка восстановление файла из корзины"},{"name":"story","value":"Проверка функции восстановления файла 'input.txt' из корзины"},{"name":"tag","value":"positive"},{"name":"parentSuite","value":"tests.restore_file"},{"name":"suite","value":"test_restore_file"},{"name":"host","value":"fv-az407-736"},{"name":"thread","value":"2314-MainThread"},{"name":"framework","value":"pytest"},{"name":"language","value":"cpython3"},{"name":"package","value":"tests.restore_file.test_restore_file"},{"name":"resultFormat","value":"allure2"}],"parameters":[],"links":[],"hidden":false,"retry":false,"extra":{"severity":"normal","retries":[],"categories":[{"name":"Test defects","matchedStatuses":[],"flaky":false}],"tags":["positive"]},"source":"d7072c92a2bee4a2.json","parameterValues":[]}